ERROR - [2022-01-04 10:19:43,501] - get_logging.py - __console : 61] : 检查数据清除出错： [Errno 22] Invalid argument: 'D:\\py_workspace\\auto_django\\auto_django\\resultfile\\2022-01-04 10:19:43__check_sql_result.xlsx'
ERROR - [2022-01-04 10:21:07,484] - get_logging.py - __console : 61] : 检查数据清除出错： [Errno 22] Invalid argument: 'D:\\py_workspace\\auto_django\\auto_django\\resultfile\\2022-01-04 10:21:07__check_sql_result.xlsx'
ERROR - [2022-01-04 10:22:24,233] - get_logging.py - __console : 61] : 检查数据清除出错： [Errno 22] Invalid argument: 'D:\\py_workspace\\auto_django\\auto_django\\resultfile\\2022-01-04 10:22:24__check_sql_result.xlsx'
ERROR - [2022-01-04 10:23:27,836] - get_logging.py - __console : 61] : 报错信息： [Errno 2] No such file or directory: 'D:\\py_workspace\\auto_django\\auto_django\\resultfile\\test.xlsx'
ERROR - [2022-01-04 10:23:31,244] - get_logging.py - __console : 61] : 报错信息： [Errno 2] No such file or directory: 'D:\\py_workspace\\auto_django\\auto_django\\resultfile\\test.xlsx'
ERROR - [2022-01-04 10:23:31,852] - get_logging.py - __console : 61] : 报错信息： [Errno 2] No such file or directory: 'D:\\py_workspace\\auto_django\\auto_django\\resultfile\\test.xlsx'
ERROR - [2022-01-04 10:23:32,547] - get_logging.py - __console : 61] : 报错信息： [Errno 2] No such file or directory: 'D:\\py_workspace\\auto_django\\auto_django\\resultfile\\test.xlsx'
ERROR - [2022-01-04 10:23:37,221] - get_logging.py - __console : 61] : 报错信息： [Errno 2] No such file or directory: 'D:\\py_workspace\\auto_django\\auto_django\\resultfile\\test.xlsx'
ERROR - [2022-01-04 18:15:42,930] - get_logging.py - __console : 61] : 获取数据出错： unsupported operand type(s) for -: 'NoneType' and 'int'
ERROR - [2022-01-04 18:16:39,704] - get_logging.py - __console : 61] : 获取数据出错： unsupported operand type(s) for -: 'NoneType' and 'int'
ERROR - [2022-01-04 18:17:12,234] - get_logging.py - __console : 61] : 获取数据出错： unsupported operand type(s) for -: 'NoneType' and 'int'
ERROR - [2022-01-04 18:17:39,877] - get_logging.py - __console : 61] : 获取数据出错： unsupported operand type(s) for -: 'NoneType' and 'int'
ERROR - [2022-01-04 18:18:19,090] - get_logging.py - __console : 61] : 获取数据出错： unsupported operand type(s) for -: 'NoneType' and 'int'
ERROR - [2022-01-04 18:18:43,385] - get_logging.py - __console : 61] : 获取数据出错： unsupported operand type(s) for -: 'NoneType' and 'int'
ERROR - [2022-01-04 18:18:57,828] - get_logging.py - __console : 61] : 获取数据出错： Negative indexing is not supported.
ERROR - [2022-01-04 18:18:58,667] - get_logging.py - __console : 61] : 获取数据出错： Negative indexing is not supported.
ERROR - [2022-01-04 18:19:07,429] - get_logging.py - __console : 61] : 获取数据出错： Negative indexing is not supported.
ERROR - [2022-01-04 18:19:26,684] - get_logging.py - __console : 61] : 获取数据出错： Negative indexing is not supported.
ERROR - [2022-01-04 18:19:44,394] - get_logging.py - __console : 61] : 获取数据出错： Negative indexing is not supported.
ERROR - [2022-01-04 18:20:30,780] - get_logging.py - __console : 61] : 获取数据出错： Negative indexing is not supported.
ERROR - [2022-01-04 18:26:07,790] - get_logging.py - __console : 61] : 获取数据出错： no such column: t_validation_test_case.country
ERROR - [2022-01-04 18:26:08,301] - get_logging.py - __console : 61] : 获取数据出错： no such column: t_validation_test_case.country
ERROR - [2022-01-04 18:26:08,526] - get_logging.py - __console : 61] : 获取数据出错： no such column: t_validation_test_case.country
